using Microsoft.VisualStudio.TestTools.UnitTesting;
using System;
using BankAccountNS;

namespace BankTest2
{
    [TestClass]
    public class UnitTest1
    {
        [TestMethod]
        public void TestMethod1()
        {
        }

        // unit test code  
        [TestMethod]
        public void Debit_WithValidAmount_UpdatesBalance()
        {
            // arrange  
            double beginningBalance = 11.99;
            double debitAmount = 4.55;
            double expected = 7.44;
            BankAccount account = new BankAccount("Mr. Bryan Walton", beginningBalance);

            // act  
            account.Debit(debitAmount);

            // assert  
            double actual = account.Balance;
            Assert.AreEqual(expected, actual, 0.001, "Account not debited correctly");
        }

        //unit test method  
        [TestMethod]
        public void Debit_WhenAmountIsMoreThanBalance_ShouldThrowArgumentOutOfRange()
        {
            // arrange  
            double beginningBalance = 11.99;
            double debitAmount = 100;
            BankAccount account = new BankAccount("Mr. Bryan Walton", beginningBalance);

            // act  

            // assert is handled by ExpectedException  

            try
            {
                account.Debit(debitAmount);
            }
            catch (ArgumentOutOfRangeException e)
            {
                // assert  
                StringAssert.Contains(e.Message, BankAccount.DebitAmountExceedsBalanceMessage);
                return;
            }
            Assert.Fail("No exception was thrown.");
        }

        //unit test method  
        [TestMethod]
        public void Debit_WhenAmountIsLessThanZero_ShouldThrowArgumentOutOfRange()
        {
            // arrange  
            double beginningBalance = 11.99;
            double debitAmount = -100.00;
            BankAccount account = new BankAccount("Mr. Bryan Walton", beginningBalance);

            // act  

            // assert is handled by ExpectedException  

            try
            {
                account.Debit(debitAmount);
            }
            catch (ArgumentOutOfRangeException e)
            {
                // assert  
                StringAssert.Contains(e.Message, BankAccount.DebitAmountLessThanZeroMessage);
                return;
            }
            Assert.Fail("No exception was thrown.");
        }

        [TestMethod]
        public void Credit_WithValidAmount_UpdatesBalance()
        {
            // arrange  
            double beginningBalance = 11.99;
            double creditAmount = 100;
            double expected = 111.99;
            BankAccount account = new BankAccount("Mr. Bryan Walton", beginningBalance);

            // act  
            account.Credit(creditAmount);

            // assert  
            double actual = account.Balance;
            Assert.AreEqual(expected, actual, 0.001, "Account not credited correctly");
        }

        [TestMethod]
        public void Credit_WhenAccountIsFrozen_ShouldThrowException()
        {
            // arrange  
            double beginningBalance = 11.99;
            double creditAmount = 100.00;
            BankAccount account = new BankAccount("Mr. Bryan Walton", beginningBalance);
            account.ToggleFreeze();
            // act  
 

            account.Credit(creditAmount);
        }

        [TestMethod]
        public void Credit_WhenAmountIsLessThanZero_ShouldThrowArgumentOutOfRange()
        {
            // arrange  
            double beginningBalance = 11.99;
            double creditAmount = -100.00;
            BankAccount account = new BankAccount("Mr. Bryan Walton", beginningBalance);

            // act  

            // assert is handled by ExpectedException  

            try
            {
                account.Credit(creditAmount);
            }
            catch (ArgumentOutOfRangeException e)
            {
                // assert  
                StringAssert.Contains(e.Message, BankAccount.CreditAmountLessThanZeroMessage);
                return;
            }
            Assert.Fail("No exception was thrown.");
        }
    }
}
